Workbook
Name Slicer_Channel: #N/A
Name Slicer_Channel1: #N/A
Name Slicer_Country: #N/A
Name Slicer_Country1: #N/A
Name Slicer_Months__OrderDate: #N/A
Name Slicer_PaymentMethod: #N/A
Name Slicer_ProductCategory: #N/A
Name Slicer_Region: #N/A
Name Slicer_Region1: #N/A
Name Slicer_ShippingDays: #N/A
Name Slicer_Years__OrderDate: #N/A
Name Slicer_Years__OrderDate1: #N/A

Sheet SalesData
A1: OrderID | B1: OrderDate1 | C1: OrderDate | D1: CustomerID | E1: Region | F1: Country | G1: City | H1: ProductCategory | I1: ProductName | J1: Sales | K1: Quantity | L1: Discount | M1: Profit | N1: Channel | O1: PaymentMethod | P1: ShippingDays
A2: ORD00001 | B2: 2024-11-14 | C2: =DATEVALUE(Table1[[#This Row],[OrderDate1]]) -> 45610 | D2: CUST5736 | E2: Asia | F2: Germany | G2: Mumbai | H2: Home | I2: Sofa | J2: 435.18 | K2: 5 | L2: 0.21 | M2: 146.93 | N2: Marketplace | O2: Credit Card | P2: 9
A3: ORD00002 | B3: 2024-06-01 | C3: =DATEVALUE(Table1[[#This Row],[OrderDate1]]) -> 45444 | D3: CUST4952 | E3: Asia | F3: Germany | G3: London | H3: Beauty | I3: Perfume | J3: 958.75 | K3: 1 | L3: 0.24 | M3: 117.66 | N3: Mobile App | O3: Debit Card | P3: 4
A4: ORD00003 | B4: 2025-11-13 | C4: =DATEVALUE(Table1[[#This Row],[OrderDate1]]) -> 45974 | D4: CUST9494 | E4: Africa | F4: France | G4: Delhi | H4: Home | I4: Shoes | J4: 4582.78 | K4: 5 | L4: 0.1 | M4: 1588.84 | N4: Mobile App | O4: Net Banking | P4: 5
A5: ORD00004 | B5: 2024-02-18 | C5: =DATEVALUE(Table1[[#This Row],[OrderDate1]]) -> 45340 | D5: CUST3889 | E5: Middle East | F5: USA | G5: Toronto | H5: Electronics | I5: Perfume | J5: 3771.2 | K5: 4 | L5: 0.13 | M5: 1044.58 | N5: Marketplace | O5: Debit Card | P5: 10
A6: ORD00005 | B6: 2024-05-31 | C6: =DATEVALUE(Table1[[#This Row],[OrderDate1]]) -> 45443 | D6: CUST8584 | E6: Africa | F6: UK | G6: New York | H6: Electronics | I6: Mixer | J6: 1588.48 | K6: 5 | L6: 0.19 | M6: 198.67 | N6: Website | O6: Debit Card | P6: 7
A7: ORD00006 | B7: 2024-12-27 | C7: =DATEVALUE(Table1[[#This Row],[OrderDate1]]) -> 45653 | D7: CUST1996 | E7: Asia | F7: Canada | G7: Berlin | H7: Electronics | I7: Watch | J7: 1002.02 | K7: 3 | L7: 0.03 | M7: 137.17 | N7: Website | O7: Debit Card | P7: 6
A8: ORD00007 | B8: 2024-07-12 | C8: =DATEVALUE(Table1[[#This Row],[OrderDate1]]) -> 45485 | D8: CUST4101 | E8: Europe | F8: UAE | G8: Toronto | H8: Fashion | I8: T-shirt | J8: 1581.8 | K8: 3 | L8: 0.25 | M8: 527.13 | N8: Marketplace | O8: Credit Card | P8: 1
A9: ORD00008 | B9: 2024-01-20 | C9: =DATEVALUE(Table1[[#This Row],[OrderDate1]]) -> 45311 | D9: CUST1995 | E9: Middle East | F9: India | G9: Berlin | H9: Beauty | I9: Headphones | J9: 1939.59 | K9: 2 | L9: 0.03 | M9: 635.15 | N9: Website | O9: Debit Card | P9: 9
A10: ORD00009 | B10: 2024-10-22 | C10: =DATEVALUE(Table1[[#This Row],[OrderDate1]]) -> 45587 | D10: CUST1088 | E10: Africa | F10: USA | G10: Berlin | H10: Fashion | I10: Laptop | J10: 701.36 | K10: 2 | L10: 0.28 | M10: 73.38 | N10: Mobile App | O10: UPI | P10: 6
A11: ORD00010 | B11: 2024-03-05 | C11: =DATEVALUE(Table1[[#This Row],[OrderDate1]]) -> 45356 | D11: CUST1781 | E11: Middle East | F11: USA | G11: New York | H11: Sports | I11: Backpack | J11: 2752.5 | K11: 4 | L11: 0.06 | M11: 379.55 | N11: Website | O11: Credit Card | P11: 8 | S11: =COUNT((Table1[CustomerID])) -> 0
A12: ORD00011 | B12: 2024-07-03 | C12: =DATEVALUE(Table1[[#This Row],[OrderDate1]]) -> 45476 | D12: CUST5824 | E12: Europe | F12: France | G12: Delhi | H12: Electronics | I12: Backpack | J12: 2861.09 | K12: 5 | L12: 0.29 | M12: 816.79 | N12: Website | O12: Cash on Delivery | P12: 10
A13: ORD00012 | B13: 2024-08-06 | C13: =DATEVALUE(Table1[[#This Row],[OrderDate1]]) -> 45510 | D13: CUST3833 | E13: Asia | F13: Germany | G13: Berlin | H13: Fashion | I13: Mixer | J13: 1805.24 | K13: 2 | L13: 0.05 | M13: 199.7 | N13: Website | O13: Debit Card | P13: 9
A14: ORD00013 | B14: 2025-05-31 | C14: =DATEVALUE(Table1[[#This Row],[OrderDate1]]) -> 45808 | D14: CUST9273 | E14: Asia | F14: India | G14: Toronto | H14: Sports | I14: T-shirt | J14: 1159.85 | K14: 4 | L14: 0.11 | M14: 197.73 | N14: Mobile App | O14: Net Banking | P14: 8
A15: ORD00014 | B15: 2025-01-28 | C15: =DATEVALUE(Table1[[#This Row],[OrderDate1]]) -> 45685 | D15: CUST1732 | E15: Asia | F15: France | G15: Toronto | H15: Fashion | I15: Backpack | J15: 184.5 | K15: 1 | L15: 0.24 | M15: 28.47 | N15: Marketplace | O15: Cash on Delivery | P15: 4
A16: ORD00015 | B16: 2025-06-23 | C16: =DATEVALUE(Table1[[#This Row],[OrderDate1]]) -> 45831 | D16: CUST9571 | E16: Middle East | F16: India | G16: Delhi | H16: Beauty | I16: Headphones | J16: 1915.53 | K16: 5 | L16: 0.26 | M16: 339.55 | N16: Mobile App | O16: Credit Card | P16: 2
A17: ORD00016 | B17: 2024-11-06 | C17: =DATEVALUE(Table1[[#This Row],[OrderDate1]]) -> 45602 | D17: CUST4819 | E17: North America | F17: USA | G17: London | H17: Fashion | I17: Watch | J17: 766.04 | K17: 1 | L17: 0.17 | M17: 147.77 | N17: Marketplace | O17: UPI | P17: 9
A18: ORD00017 | B18: 2024-06-12 | C18: =DATEVALUE(Table1[[#This Row],[OrderDate1]]) -> 45455 | D18: CUST7713 | E18: Africa | F18: France | G18: Dubai | H18: Fashion | I18: Perfume | J18: 1979.86 | K18: 2 | L18: 0.2 | M18: 540.21 | N18: Mobile App | O18: Credit Card | P18: 3
A19: ORD00018 | B19: 2025-05-23 | C19: =DATEVALUE(Table1[[#This Row],[OrderDate1]]) -> 45800 | D19: CUST4258 | E19: Middle East | F19: UAE | G19: Berlin | H19: Sports | I19: Watch | J19: 2945.11 | K19: 4 | L19: 0.21 | M19: 703.61 | N19: Mobile App | O19: Credit Card | P19: 1
A20: ORD00019 | B20: 2025-04-01 | C20: =DATEVALUE(Table1[[#This Row],[OrderDate1]]) -> 45748 | D20: CUST7741 | E20: North America | F20: France | G20: New York | H20: Sports | I20: Perfume | J20: 2056.11 | K20: 5 | L20: 0.04 | M20: 257.08 | N20: Mobile App | O20: Credit Card | P20: 9
A21: ORD00020 | B21: 2025-07-28 | C21: =DATEVALUE(Table1[[#This Row],[OrderDate1]]) -> 45866 | D21: CUST8004 | E21: Africa | F21: UAE | G21: Paris | H21: Fashion | I21: Laptop | J21: 2747.4 | K21: 4 | L21: 0.09 | M21: 561.4 | N21: Marketplace | O21: Debit Card | P21: 5
A22: ORD00021 | B22: 2024-03-21 | C22: =DATEVALUE(Table1[[#This Row],[OrderDate1]]) -> 45372 | D22: CUST5139 | E22: North America | F22: India | G22: Berlin | H22: Beauty | I22: Laptop | J22: 1342.64 | K22: 4 | L22: 0.13 | M22: 409.84 | N22: Website | O22: Credit Card | P22: 1
A23: ORD00022 | B23: 2024-02-22 | C23: =DATEVALUE(Table1[[#This Row],[OrderDate1]]) -> 45344 | D23: CUST4525 | E23: Asia | F23: Canada | G23: London | H23: Sports | I23: Watch | J23: 230.12 | K23: 1 | L23: 0.22 | M23: 28.15 | N23: Marketplace | O23: Net Banking | P23: 5
... A1001: ORD01000 | B1001: 2025-11-23 | C1001: =DATEVALUE(Table1[[#This Row],[OrderDate1]]) -> 45984 | D1001: CUST7335 | E1001: Europe | F1001: USA | G1001: Paris | H1001: Home | I1001: Mixer | J1001: 1719.37 | K1001: 5 | L1001: 0.01 | M1001: 543.1 | N1001: Website | O1001: Credit Card | P1001: 2

Sheet Sheet1
AP4: (KPI cards) | AV4: PIVOT TABLES | AY4: Row Labels | AZ4: Sum of Sales | BC4: Row Labels | BD4: Sum of Sales | BL4: Sales Performance Dashboard
AY5: Africa | AZ5: 0.2193049 | BC5: Dubai | BD5: 0.53079909 | BF5: Row Labels | BG5: Average of Profit | BH5: Row Labels | BI5: Average of Profit
AP6: Sum of Sales | AR6: Total orders | AV6: Row Labels | AW6: Sum of Sales | AX6: Sum of Profit | AY6: Europe | AZ6: 0.21501267 | BC6: Berlin | BD6: 0.24265041 | BF6: 0 | BG6: 0.83462597 | BH6: 0 | BI6: 1.7336132 | BL6: 1. What is the total sales and profit by year/month?
AP7: 1527452.5 | AR7: =COUNTA(SalesData!B2:B1001) -> 1000 | AV7: 2024 | AW7: 0.54269734 | AX7: 0.53501499 | AY7: Middle East | AZ7: 0.19428922 | BC7: New York | BD7: 0.15259322 | BF7: 0.01 | BG7: 1.023113 | BH7: 0.01 | BI7: 0.78658595
AV8: Jan | AW8: 0.045422172 | AX8: 0.050058076 | AY8: Asia | AZ8: 0.18707074 | BC8: Paris | BD8: 0.073957269 | BF8: 0.02 | BG8: 1.0742686 | BH8: 0.02 | BI8: 0.93303087 | BL8: 2. Which region generates the highest revenue?
AP9: Sum of Profit | AR9: Total Customers | AV9: Feb | AW9: 0.046504452 | AX9: 0.044146325 | AY9: North America | AZ9: 0.18432247 | BC9: Grand Total | BD9: 1 | BF9: 0.03 | BG9: 0.14596846 | BH9: 0.03 | BI9: 0.3452371
AP10: 345002.67 | AR10: =COUNTA(_xlfn.UNIQUE(SalesData!D2:D1001)) -> 956 | AV10: Mar | AW10: 0.043518702 | AX10: 0.046209497 | AY10: Grand Total | AZ10: 1 | BF10: 0.04 | BG10: 1.3198158 | BH10: 0.04 | BI10: 0.62802196 | BL10: 3. Which country and city perform best?
AV11: Apr | AW11: 0.038990398 | AX11: 0.037761157 | BF11: 0.05 | BG11: 0.7001899 | BH11: 0.05 | BI11: 0.93129841
AS12: Row Labels | AT12: Sum of Sales | AV12: May | AW12: 0.045393484 | AX12: 0.043738357 | AY12: Row Labels | AZ12: Sum of Sales | BF12: 0.06 | BG12: 0.89565491 | BH12: 0.06 | BI12: 1.2436601 | BL12: 4. What is the monthly sales trend?
AS13: Fashion | AT13: 340214.32 | AV13: Jun | AW13: 0.043157133 | AX13: 0.040387861 | AY13: Fashion | AZ13: 0.22273316 | BF13: 0.07 | BG13: 1.7812983 | BH13: 0.07 | BI13: 0.59778723
AS14: Grand Total | AT14: 340214.32 | AV14: Jul | AW14: 0.037116042 | AX14: 0.038901554 | AY14: Beauty | AZ14: 0.20613192 | BF14: 0.08 | BG14: 0.5363129 | BH14: 0.08 | BI14: 0.41040842 | BL14: 5. Which product category contributes most to sales?
AV15: Aug | AW15: 0.049225584 | AX15: 0.052360493 | AY15: Sports | AZ15: 0.1982308 | BB15: Row Labels | BC15: Sum of Sales | BD15: Sum of Profit | BF15: 0.09 | BG15: 2.8187495 | BH15: 0.09 | BI15: 1.123375
AS16: Row Labels | AT16: Sum of Sales | AV16: Sep | AW16: 0.059986049 | AX16: 0.056380694 | AY16: Home | AZ16: 0.19135572 | BB16: Canada | BC16: 0.1446995 | BD16: 0.10976622 | BF16: 0.1 | BG16: 0.59173017 | BH16: 0.1 | BI16: 0.61232982 | BL16: 6. Which are the top 10 products by sales?
AS17: Africa | AT17: 334977.81 | AV17: Oct | AW17: 0.041380181 | AX17: 0.034424574 | AY17: Electronics | AZ17: 0.1815484 | BB17: France | BC17: 0.16543944 | BD17: 0.18727754 | BF17: 0.11 | BG17: 0.32529788 | BH17: 0.11 | BI17: 1.8643002
AS18: Grand Total | AT18: 334977.81 | AV18: Nov | AW18: 0.0342355 | AX18: 0.034245938 | AY18: Grand Total | AZ18: 1 | BB18: Germany | BC18: 0.19511935 | BD18: 0.19967376 | BF18: 0.12 | BG18: 0.29011516 | BH18: 0.12 | BI18: 1.1162317 | BL18: 7. Which category has the highest profit margin?
AV19: Dec | AW19: 0.057767643 | AX19: 0.056400462 | BB19: India | BC19: 0.10721351 | BD19: 0.08004645 | BF19: 0.13 | BG19: 0.56274468 | BH19: 0.13 | BI19: 1.104122
AV20: 2025 | AW20: 0.45730266 | AX20: 0.46498501 | BB20: UAE | BC20: 0.079213664 | BD20: 0.10139984 | BF20: 0.14 | BG20: 0.47616232 | BH20: 0.14 | BI20: 0.89008667 | BL20: 8. Which sales channel performs best?
AP21: Average of Profit Margin | AV21: Jan | AW21: 0.039841167 | AX21: 0.03914648 | BB21: UK | BC21: 0.13311661 | BD21: 0.11811401 | BF21: 0.15 | BG21: 0.42495787 | BH21: 0.15 | BI21: 1.3759183
AP22: 0.22586802 | AV22: Feb | AW22: 0.034274854 | AX22: 0.032510647 | BB22: USA | BC22: 0.17519794 | BD22: 0.20372217 | BF22: 0.16 | BG22: 0.62063433 | BH22: 0.16 | BI22: 0.68733508 | BL22: 9. How does discount impact profit?
AV23: Mar | AW23: 0.028475413 | AX23: 0.029999971 | BB23: Grand Total | BC23: 1 | BD23: 1 | BF23: 0.17 | BG23: 1.3279866 | BH23: 0.17 | BI23: 0.84992505
AV24: Apr | AW24: 0.0414968 | AX24: 0.046852362 | BF24: 0.18 | BG24: 3.765804 | BH24: 0.18 | BI24: 0.51229402 | BL24: 10. Which country contributes the highest revenue and profit?
AV25: May | AW25: 0.037428863 | AX25: 0.038309617 | AZ25: Row Labels | BA25: Sum of Sales | BC25: Row Labels | BD25: Sum of Sales | BF25: 0.19 | BG25: 0.07888868 | BH25: 0.19 | BI25: 1.2166963
AV26: Jun | AW26: 0.04245245 | AX26: 0.042342484 | AZ26: Shoes | BA26: 0.20763693 | BC26: Marketplace | BD26: 0.40885078 | BF26: 0.2 | BG26: 0.026350446 | BH26: 0.2 | BI26: 1.7849442
AV27: Jul | AW27: 0.029317279 | AX27: 0.033863738 | AZ27: Headphones | BA27: 0.16463932 | BC27: Mobile App | BD27: 0.28110641 | BF27: 0.21 | BG27: 0.7900254 | BH27: 0.21 | BI27: 1.1087032
AV28: Aug | AW28: 0.045153234 | AX28: 0.04272164 | AZ28: Mixer | BA28: 0.15350382 | BC28: Website | BD28: 0.31004281 | BF28: 0.22 | BG28: 3.0255192 | BH28: 0.22 | BI28: 0.8991775
AV29: Sep | AW29: 0.02829743 | AX29: 0.030776168 | AZ29: Perfume | BA29: 0.13035619 | BC29: Grand Total | BD29: 1 | BF29: 0.23 | BG29: 0.70997644 | BH29: 0.23 | BI29: 0.6885677 | BL29: Operations & Logistics Dashboard
AV30: Oct | AW30: 0.044918072 | AX30: 0.042292455 | AZ30: Sofa | BA30: 0.12558769 | BF30: 0.24 | BG30: 0.38655453 | BH30: 0.24 | BI30: 1.3446731
AV31: Nov | AW31: 0.036704998 | AX31: 0.038530745 | AZ31: Backpack | BA31: 0.075321771 | BC31: Row Labels | BD31: Sum of Sales | BF31: 0.25 | BG31: 1.7148285 | BH31: 0.25 | BI31: 0.92575122 | BL31: 1. What percentage of orders ship within 1–3, 4–6, and 7+ days?
AV32: Dec | AW32: 0.048942099 | AX32: 0.047638704 | AZ32: Watch | BA32: 0.074156646 | BC32: 2024 | BD32: 0.51075774 | BF32: 0.26 | BG32: 1.5550667 | BH32: 0.26 | BI32: 0.76788905
AV33: Grand Total | AW33: 1 | AX33: 1 | AZ33: Laptop | BA33: 0.035225832 | BC33: 2025 | BD33: 0.48924226 | BF33: 0.27 | BG33: 1.9849043 | BH33: 0.27 | BI33: 1.1585883 | BL33: 2. Which regions have the fastest vs slowest delivery times?
AZ34: T-shirt | BA34: 0.033571801 | BC34: Grand Total | BD34: 1 | BF34: 0.28 | BG34: 1.149259 | BH34: 0.28 | BI34: 0.99803793
AZ35: Grand Total | BA35: 1 | BF35: 0.3 | BG35: 1.4341799 | BH35: 0.29 | BI35: 1.375523 | BL35: 3. What is the correlation between discount % and quantity sold?
BF36: Grand Total | BG36: 1 | BH36: 0.3 | BI36: 1.1732445
BH37: Grand Total | BI37: 1 | BL37: 4. Does shipping time affect repeat purchases?
BL39: 5. What is the quantity sold by category?

Sheet Sheet2
AI1: Difference new - return customers | AL1: Row Labels | AM1: Count of CustomerID | AP1: Row Labels | AQ1: Distinct Count of CustomerID | AS1: Customer Behavior & Segmentation Dashboard
AI2: TOTAL CUST | AJ2: =COUNTA(SalesData!D2:D1001) -> 1000 | AL2: Marketplace | AM2: 0.36 | AP2: Africa | AQ2: 191
AI3: UNIQUE CUST | AJ3: =COUNTA(_xlfn.UNIQUE(SalesData!D2:D1001)) -> 956 | AL3: Mobile App | AM3: 0.312 | AP3: Asia | AQ3: 199 | AS3: 10. What is the difference between new vs returning customers?
AI4: NEW CUST | AJ4: =COUNTA(Sheet2!AJ24:AJ935) -> 912 | AL4: Website | AM4: 0.328 | AP4: Europe | AQ4: 205
AI5: RETURN CUST | AL5: Grand Total | AM5: 1 | AP5: Middle East | AQ5: 201 | AS5: 1. How many unique customers are there?
AI6: REPEAT CUST RATIO | AJ6: =AJ5/AJ2 -> 0 | AP6: North America | AQ6: 196
AL7: Row Labels | AM7: Count of CustomerID | AP7: Grand Total | AQ7: 956 | AS7: (based on CustomerID)
AI8: Row Labels | AJ8: Count of CustomerID | AL8: Cash on Delivery | AM8: 184
AI9: Marketplace | AJ9: 360 | AL9: Credit Card | AM9: 213 | AP9: Row Labels | AQ9: Distinct Count of CustomerID | AS9: ✔ 2. Which region has the highest number of customers?
AI10: Grand Total | AJ10: 360 | AL10: Debit Card | AM10: 206 | AP10: Canada | AQ10: 130
AL11: Net Banking | AM11: 188 | AP11: France | AQ11: 155 | AS11: ✔ 3. Which city and country have the most customers?
AI12: Row Labels | AJ12: Count of CustomerID | AL12: UPI | AM12: 209 | AP12: Germany | AQ12: 133
AI13: Credit Card | AJ13: 213 | AL13: Grand Total | AM13: 1000 | AP13: India | AQ13: 143 | AS13: ✔ 4. What is the repeat customer ratio?
AI14: Grand Total | AJ14: 213 | AP14: UAE | AQ14: 139
AL15: Row Labels | AM15: Sum of Sales | AP15: UK | AQ15: 145 | AS15: New vs Returning customers → use:
AI16: New Customers | AJ16: =COUNTIF(AJ24:AJ979,1) -> 912 | AL16: CUST7566 | AM16: 0.43087561 | AP16: USA | AQ16: 148
AI17: Returning Customers | AJ17: =COUNTIF(AJ24:AJ979,">1") -> 44 | AL17: CUST8749 | AM17: 0.24326286 | AP17: Grand Total | AQ17: 956 | AS17: COUNT of customers with 1 order
AL18: CUST8815 | AM18: 0.15200423
AI19: Catergory | AJ19: Count | AL19: CUST6095 | AM19: 0.11982371 | AP19: Row Labels | AQ19: Distinct Count of CustomerID | AS19: COUNT of customers with >1 order
AI20: New Customers | AJ20: =AJ16 -> 912 | AL20: CUST2692 | AM20: 0.054033587 | AP20: Berlin | AQ20: 141
AI21: Returning Customers | AJ21: =AJ17 -> 44 | AL21: Grand Total | AM21: 1 | AP21: Delhi | AQ21: 129 | AS21: ✔ 5. What is the average order value (AOV) by region?
AP22: Dubai | AQ22: 131
AI23: Row Labels | AJ23: Count of OrderDate1 | AP23: London | AQ23: 118 | AS23: ✔ 6. What is the average discount given to each region?
AI24: CUST1013 | AJ24: 1 | AL24: Avg Order Per Customer | AP24: Mumbai | AQ24: 111
AI25: CUST1021 | AJ25: 1 | AL25: =AVERAGE(Sheet2!AJ24:AJ979) -> 1.0460251 | AP25: New York | AQ25: 133 | AS25: ✔ 7. What is the average shipping time by region?
AI26: CUST1024 | AJ26: 1 | AP26: Paris | AQ26: 114
AI27: CUST1065 | AJ27: 1 | AP27: Toronto | AQ27: 116 | AS27: ✔ 8. Which channel (Online/Offline/Marketplace) is most preferred?
AI28: CUST1066 | AJ28: 1 | AL28: Row Labels | AM28: Average of Discount | AP28: Grand Total | AQ28: 956
AI29: CUST1088 | AJ29: 1 | AL29: Africa | AM29: 0.14505155 | AS29: ✔ 9. Which payment method is used the most?
AI30: CUST1089 | AJ30: 1 | AL30: Asia | AM30: 0.15246231
AI31: CUST1107 | AJ31: 1 | AL31: Europe | AM31: 0.13754808 | AS31: ✔ 10. Who are the top 10 customers by total spending?
AI32: CUST1110 | AJ32: 1 | AL32: Middle East | AM32: 0.14681592
AI33: CUST1122 | AJ33: 1 | AL33: North America | AM33: 0.15565657 | AQ33: Column1 | AR33: Column2
AI34: CUST1131 | AJ34: 1 | AL34: Grand Total | AM34: 0.14742 | AQ34: Canada | AR34: 130
AI35: CUST1132 | AJ35: 1 | AQ35: France | AR35: 155
AI36: CUST1138 | AJ36: 1 | AL36: Row Labels | AM36: Average of ShippingDays | AQ36: Germany | AR36: 133
AI37: CUST1144 | AJ37: 1 | AL37: Africa | AM37: 5.5051546 | AQ37: India | AR37: 143
AI38: CUST1147 | AJ38: 1 | AL38: Asia | AM38: 5.5577889 | AQ38: UAE | AR38: 139
AI39: CUST1155 | AJ39: 1 | AL39: Europe | AM39: 5.7932692 | AQ39: UK | AR39: 145
AI40: CUST1157 | AJ40: 1 | AL40: Middle East | AM40: 5.5273632 | AQ40: USA | AR40: 148
...
